Workbook

Sheet Requerimientos
B1: *La estimación no incluye la etapa de evaluación.
B2: Requerimiento | C2: Nro RSIS/Componente | D2: Descripción | E2: Dificultad | G2: Estimación Esfuerzo | H2: Anállisis y Diseño | K2: Desarrollo | N2: Testing | Q2: Otros | S2: Juicio Experto | T2: Estimación Ofrecida | U2: Real | W2: Dif Experto vs Estimados
E3: Código | F3: Descripción | H3: Esfuerzo | I3: Ajust. +/- | J3: Esfuerzo Ajustado | K3: Esfuerzo | L3: Ajust. +/- | M3: Esfuerzo Ajustado | N3: Esfuerzo | O3: Ajust. +/- | P3: Esfuerzo Ajustado
C4: 1 | D4: HU008: Proceso de Valorización Cartera esquema especial | E4: 3 | F4: =VLOOKUP(E4,Parámetros!$B$13:$C$23,2,FALSE) -> Media Baja | G4: =J4+M4+P4+Q4 -> 23.28 | H4: =IF(E4=0,0,VLOOKUP(E4,Tabla!$C$6:$F$15,4,FALSE)) -> 2.48 | J4: =H4+I4 -> 2.48 | K4: =IF(E4=0,0,VLOOKUP(E4,Tabla!$C$6:$G$15,5,FALSE)) -> 12.4 | L4: 2 | M4: =K4+L4 -> 14.4 | N4: =IF(E4=0,0,VLOOKUP(E4,Tabla!$C$6:$H$15,6,FALSE)) -> 5 | P4: =N4+O4 -> 5 | Q4: =IF(E4=0,0,VLOOKUP(E4,Tabla!$C$6:$I$15,7,FALSE)) -> 1.4 | R4: =M4+P4+Q4 -> 20.8
C5: =C4+1 -> 2 | D5: HU009: Confirmación del Proceso de Valorización | E5: 1 | F5: =VLOOKUP(E5,Parámetros!$B$13:$C$23,2,FALSE) -> Muy Baja | G5: =J5+M5+P5+Q5 -> 10.64 | H5: =IF(E5=0,0,VLOOKUP(E5,Tabla!$C$6:$F$15,4,FALSE)) -> 1.24 | J5: =H5+I5 -> 1.24 | K5: =IF(E5=0,0,VLOOKUP(E5,Tabla!$C$6:$G$15,5,FALSE)) -> 6.2 | M5: =K5+L5 -> 6.2 | N5: =IF(E5=0,0,VLOOKUP(E5,Tabla!$C$6:$H$15,6,FALSE)) -> 2.5 | P5: =N5+O5 -> 2.5 | Q5: =IF(E5=0,0,VLOOKUP(E5,Tabla!$C$6:$I$15,7,FALSE)) -> 0.7 | R5: =M5+P5+Q5 -> 9.4
C6: =C5+1 -> 3 | D6: HU010: Liquidación de operaciones | E6: 1 | F6: =VLOOKUP(E6,Parámetros!$B$13:$C$23,2,FALSE) -> Muy Baja | G6: =J6+M6+P6+Q6 -> 10.64 | H6: =IF(E6=0,0,VLOOKUP(E6,Tabla!$C$6:$F$15,4,FALSE)) -> 1.24 | J6: =H6+I6 -> 1.24 | K6: =IF(E6=0,0,VLOOKUP(E6,Tabla!$C$6:$G$15,5,FALSE)) -> 6.2 | M6: =K6+L6 -> 6.2 | N6: =IF(E6=0,0,VLOOKUP(E6,Tabla!$C$6:$H$15,6,FALSE)) -> 2.5 | P6: =N6+O6 -> 2.5 | Q6: =IF(E6=0,0,VLOOKUP(E6,Tabla!$C$6:$I$15,7,FALSE)) -> 0.7 | R6: =M6+P6+Q6 -> 9.4
C7: =C6+1 -> 4 | D7: HU011: Reporte Solicitud de Reembolso - Nuevo | E7: 2 | F7: =VLOOKUP(E7,Parámetros!$B$13:$C$23,2,FALSE) -> Baja | G7: =J7+M7+P7+Q7 -> 14.896 | H7: =IF(E7=0,0,VLOOKUP(E7,Tabla!$C$6:$F$15,4,FALSE)) -> 1.736 | J7: =H7+I7 -> 1.736 | K7: =IF(E7=0,0,VLOOKUP(E7,Tabla!$C$6:$G$15,5,FALSE)) -> 8.68 | M7: =K7+L7 -> 8.68 | N7: =IF(E7=0,0,VLOOKUP(E7,Tabla!$C$6:$H$15,6,FALSE)) -> 3.5 | P7: =N7+O7 -> 3.5 | Q7: =IF(E7=0,0,VLOOKUP(E7,Tabla!$C$6:$I$15,7,FALSE)) -> 0.98 | R7: =M7+P7+Q7 -> 13.16
C8: =C7+1 -> 5 | D8: HU012: Reporte Resumen de Valorización - Adecuación | E8: 1 | F8: =VLOOKUP(E8,Parámetros!$B$13:$C$23,2,FALSE) -> Muy Baja | G8: =J8+M8+P8+Q8 -> 10.64 | H8: =IF(E8=0,0,VLOOKUP(E8,Tabla!$C$6:$F$15,4,FALSE)) -> 1.24 | J8: =H8+I8 -> 1.24 | K8: =IF(E8=0,0,VLOOKUP(E8,Tabla!$C$6:$G$15,5,FALSE)) -> 6.2 | M8: =K8+L8 -> 6.2 | N8: =IF(E8=0,0,VLOOKUP(E8,Tabla!$C$6:$H$15,6,FALSE)) -> 2.5 | P8: =N8+O8 -> 2.5 | Q8: =IF(E8=0,0,VLOOKUP(E8,Tabla!$C$6:$I$15,7,FALSE)) -> 0.7 | R8: =M8+P8+Q8 -> 9.4
C9: =C8+1 -> 6 | D9: HU013: Reporte Operaciones Vigentes - Adecuación | E9: 1 | F9: =VLOOKUP(E9,Parámetros!$B$13:$C$23,2,FALSE) -> Muy Baja | G9: =J9+M9+P9+Q9 -> 10.64 | H9: =IF(E9=0,0,VLOOKUP(E9,Tabla!$C$6:$F$15,4,FALSE)) -> 1.24 | J9: =H9+I9 -> 1.24 | K9: =IF(E9=0,0,VLOOKUP(E9,Tabla!$C$6:$G$15,5,FALSE)) -> 6.2 | M9: =K9+L9 -> 6.2 | N9: =IF(E9=0,0,VLOOKUP(E9,Tabla!$C$6:$H$15,6,FALSE)) -> 2.5 | P9: =N9+O9 -> 2.5 | Q9: =IF(E9=0,0,VLOOKUP(E9,Tabla!$C$6:$I$15,7,FALSE)) -> 0.7 | R9: =M9+P9+Q9 -> 9.4
C10: =C9+1 -> 7 | D10: HU014: Reporte de Vcto Anticipado Repo con Garantía - Adecuación | E10: 1 | F10: =VLOOKUP(E10,Parámetros!$B$13:$C$23,2,FALSE) -> Muy Baja | G10: =J10+M10+P10+Q10 -> 10.64 | H10: =IF(E10=0,0,VLOOKUP(E10,Tabla!$C$6:$F$15,4,FALSE)) -> 1.24 | J10: =H10+I10 -> 1.24 | K10: =IF(E10=0,0,VLOOKUP(E10,Tabla!$C$6:$G$15,5,FALSE)) -> 6.2 | M10: =K10+L10 -> 6.2 | N10: =IF(E10=0,0,VLOOKUP(E10,Tabla!$C$6:$H$15,6,FALSE)) -> 2.5 | P10: =N10+O10 -> 2.5 | Q10: =IF(E10=0,0,VLOOKUP(E10,Tabla!$C$6:$I$15,7,FALSE)) -> 0.7
C11: =C10+1 -> 8 | F11: =VLOOKUP(E11,Parámetros!$B$13:$C$23,2,FALSE) -> Ninguna | G11: =J11+M11+P11+Q11 -> 0 | H11: =IF(E11=0,0,VLOOKUP(E11,Tabla!$C$6:$F$15,4,FALSE)) -> 0 | J11: =H11+I11 -> 0 | K11: =IF(E11=0,0,VLOOKUP(E11,Tabla!$C$6:$G$15,5,FALSE)) -> 0 | M11: =K11+L11 -> 0 | N11: =IF(E11=0,0,VLOOKUP(E11,Tabla!$C$6:$H$15,6,FALSE)) -> 0 | P11: =N11+O11 -> 0 | Q11: =IF(E11=0,0,VLOOKUP(E11,Tabla!$C$6:$I$15,7,FALSE)) -> 0
C12: =C11+1 -> 9 | F12: =VLOOKUP(E12,Parámetros!$B$13:$C$23,2,FALSE) -> Ninguna | G12: =J12+M12+P12+Q12 -> 0 | H12: =IF(E12=0,0,VLOOKUP(E12,Tabla!$C$6:$F$15,4,FALSE)) -> 0 | J12: =H12+I12 -> 0 | K12: =IF(E12=0,0,VLOOKUP(E12,Tabla!$C$6:$G$15,5,FALSE)) -> 0 | M12: =K12+L12 -> 0 | N12: =IF(E12=0,0,VLOOKUP(E12,Tabla!$C$6:$H$15,6,FALSE)) -> 0 | P12: =N12+O12 -> 0 | Q12: =IF(E12=0,0,VLOOKUP(E12,Tabla!$C$6:$I$15,7,FALSE)) -> 0
C13: =C12+1 -> 10 | F13: =VLOOKUP(E13,Parámetros!$B$13:$C$23,2,FALSE) -> Ninguna | G13: =J13+M13+P13+Q13 -> 0 | H13: =IF(E13=0,0,VLOOKUP(E13,Tabla!$C$6:$F$15,4,FALSE)) -> 0 | J13: =H13+I13 -> 0 | K13: =IF(E13=0,0,VLOOKUP(E13,Tabla!$C$6:$G$15,5,FALSE)) -> 0 | M13: =K13+L13 -> 0 | N13: =IF(E13=0,0,VLOOKUP(E13,Tabla!$C$6:$H$15,6,FALSE)) -> 0 | P13: =N13+O13 -> 0 | Q13: =IF(E13=0,0,VLOOKUP(E13,Tabla!$C$6:$I$15,7,FALSE)) -> 0
C14: =C13+1 -> 11 | F14: =VLOOKUP(E14,Parámetros!$B$13:$C$23,2,FALSE) -> Ninguna | G14: =J14+M14+P14+Q14 -> 0 | H14: =IF(E14=0,0,VLOOKUP(E14,Tabla!$C$6:$F$15,4,FALSE)) -> 0 | J14: =H14+I14 -> 0 | K14: =IF(E14=0,0,VLOOKUP(E14,Tabla!$C$6:$G$15,5,FALSE)) -> 0 | M14: =K14+L14 -> 0 | N14: =IF(E14=0,0,VLOOKUP(E14,Tabla!$C$6:$H$15,6,FALSE)) -> 0 | P14: =N14+O14 -> 0 | Q14: =IF(E14=0,0,VLOOKUP(E14,Tabla!$C$6:$I$15,7,FALSE)) -> 0
C15: =C14+1 -> 12 | F15: =VLOOKUP(E15,Parámetros!$B$13:$C$23,2,FALSE) -> Ninguna | G15: =J15+M15+P15+Q15 -> 0 | H15: =IF(E15=0,0,VLOOKUP(E15,Tabla!$C$6:$F$15,4,FALSE)) -> 0 | J15: =H15+I15 -> 0 | K15: =IF(E15=0,0,VLOOKUP(E15,Tabla!$C$6:$G$15,5,FALSE)) -> 0 | M15: =K15+L15 -> 0 | N15: =IF(E15=0,0,VLOOKUP(E15,Tabla!$C$6:$H$15,6,FALSE)) -> 0 | P15: =N15+O15 -> 0 | Q15: =IF(E15=0,0,VLOOKUP(E15,Tabla!$C$6:$I$15,7,FALSE)) -> 0
C16: =C15+1 -> 13 | F16: =VLOOKUP(E16,Parámetros!$B$13:$C$23,2,FALSE) -> Ninguna | G16: =J16+M16+P16+Q16 -> 0 | H16: =IF(E16=0,0,VLOOKUP(E16,Tabla!$C$6:$F$15,4,FALSE)) -> 0 | J16: =H16+I16 -> 0 | K16: =IF(E16=0,0,VLOOKUP(E16,Tabla!$C$6:$G$15,5,FALSE)) -> 0 | M16: =K16+L16 -> 0 | N16: =IF(E16=0,0,VLOOKUP(E16,Tabla!$C$6:$H$15,6,FALSE)) -> 0 | P16: =N16+O16 -> 0 | Q16: =IF(E16=0,0,VLOOKUP(E16,Tabla!$C$6:$I$15,7,FALSE)) -> 0
C17: =C16+1 -> 14 | F17: =VLOOKUP(E17,Parámetros!$B$13:$C$23,2,FALSE) -> Ninguna | G17: =J17+M17+P17+Q17 -> 0 | H17: =IF(E17=0,0,VLOOKUP(E17,Tabla!$C$6:$F$15,4,FALSE)) -> 0 | J17: =H17+I17 -> 0 | K17: =IF(E17=0,0,VLOOKUP(E17,Tabla!$C$6:$G$15,5,FALSE)) -> 0 | M17: =K17+L17 -> 0 | N17: =IF(E17=0,0,VLOOKUP(E17,Tabla!$C$6:$H$15,6,FALSE)) -> 0 | P17: =N17+O17 -> 0 | Q17: =IF(E17=0,0,VLOOKUP(E17,Tabla!$C$6:$I$15,7,FALSE)) -> 0
C18: =C17+1 -> 15 | F18: =VLOOKUP(E18,Parámetros!$B$13:$C$23,2,FALSE) -> Ninguna | G18: =J18+M18+P18+Q18 -> 0 | H18: =IF(E18=0,0,VLOOKUP(E18,Tabla!$C$6:$F$15,4,FALSE)) -> 0 | J18: =H18+I18 -> 0 | K18: =IF(E18=0,0,VLOOKUP(E18,Tabla!$C$6:$G$15,5,FALSE)) -> 0 | M18: =K18+L18 -> 0 | N18: =IF(E18=0,0,VLOOKUP(E18,Tabla!$C$6:$H$15,6,FALSE)) -> 0 | P18: =N18+O18 -> 0
C19: =C18+1 -> 16 | F19: =VLOOKUP(E19,Parámetros!$B$13:$C$17,2,FALSE) -> Ninguna | G19: =SUM(G4:G18) -> 91.376 | H19: =SUM(H4:H18) -> 10.416 | I19: =SUM(I4:I18) -> 0 | J19: =SUM(J4:J18) -> 10.416 | K19: =SUM(K4:K18) -> 52.08 | L19: =SUM(L4:L18) -> 2 | M19: =SUM(M4:M18) -> 54.08 | N19: =SUM(N4:N18) -> 21 | ... Q19: =SUM(Q4:Q18) -> 5.88
B20: Costos de Transacción - CC1 | C20: =C19+1 -> 17 | F20: =VLOOKUP(E20,Parámetros!$B$13:$C$23,2,FALSE) -> Ninguna | G20: =J20+M20+P20+Q20 -> 0 | H20: =IF(E20=0,0,VLOOKUP(E20,Tabla!$C$6:$F$15,4,FALSE)) -> 0 | J20: =H20+I20 -> 0 | K20: =IF(E20=0,0,VLOOKUP(E20,Tabla!$C$6:$G$15,5,FALSE)) -> 0 | M20: =K20+L20 -> 0 | N20: =IF(E20=0,0,VLOOKUP(E20,Tabla!$C$6:$H$15,6,FALSE)) -> 0 | P20: =N20+O20 -> 0 | Q20: =IF(E20=0,0,VLOOKUP(E20,Tabla!$C$6:$I$15,7,FALSE)) -> 0 | S20: 270 | T20: 270 | W20: =+S20-G24 -> 270
C21: =C20+1 -> 18 | F21: =VLOOKUP(E21,Parámetros!$B$13:$C$23,2,FALSE) -> Ninguna | G21: =J21+M21+P21+Q21 -> 0 | H21: =IF(E21=0,0,VLOOKUP(E21,Tabla!$C$6:$F$15,4,FALSE)) -> 0 | J21: =H21+I21 -> 0 | K21: =IF(E21=0,0,VLOOKUP(E21,Tabla!$C$6:$G$15,5,FALSE)) -> 0 | M21: =K21+L21 -> 0 | N21: =IF(E21=0,0,VLOOKUP(E21,Tabla!$C$6:$H$15,6,FALSE)) -> 0 | P21: =N21+O21 -> 0 | Q21: =IF(E21=0,0,VLOOKUP(E21,Tabla!$C$6:$I$15,7,FALSE)) -> 0
C22: =C21+1 -> 19 | F22: =VLOOKUP(E22,Parámetros!$B$13:$C$23,2,FALSE) -> Ninguna | G22: =J22+M22+P22+Q22 -> 0 | H22: =IF(E22=0,0,VLOOKUP(E22,Tabla!$C$6:$F$15,4,FALSE)) -> 0 | J22: =H22+I22 -> 0 | K22: =IF(E22=0,0,VLOOKUP(E22,Tabla!$C$6:$G$15,5,FALSE)) -> 0 | M22: =K22+L22 -> 0 | N22: =IF(E22=0,0,VLOOKUP(E22,Tabla!$C$6:$H$15,6,FALSE)) -> 0 | P22: =N22+O22 -> 0 | Q22: =IF(E22=0,0,VLOOKUP(E22,Tabla!$C$6:$I$15,7,FALSE)) -> 0
C23: =C22+1 -> 20 | F23: =VLOOKUP(E23,Parámetros!$B$13:$C$23,2,FALSE) -> Ninguna | G23: =J23+M23+P23+Q23 -> 0 | H23: =IF(E23=0,0,VLOOKUP(E23,Tabla!$C$6:$F$15,4,FALSE)) -> 0 | J23: =H23+I23 -> 0 | K23: =IF(E23=0,0,VLOOKUP(E23,Tabla!$C$6:$G$15,5,FALSE)) -> 0 | M23: =K23+L23 -> 0 | N23: =IF(E23=0,0,VLOOKUP(E23,Tabla!$C$6:$H$15,6,FALSE)) -> 0 | P23: =N23+O23 -> 0 | Q23: =IF(E23=0,0,VLOOKUP(E23,Tabla!$C$6:$I$15,7,FALSE)) -> 0
C24: =C23+1 -> 21 | F24: =VLOOKUP(E24,Parámetros!$B$13:$C$17,2,FALSE) -> Ninguna | G24: =SUM(G20:G23) -> 0 | H24: =SUM(H20:H23) -> 0 | I24: =SUM(I20:I23) -> 0 | J24: =SUM(J20:J23) -> 0 | K24: =SUM(K20:K23) -> 0 | L24: =SUM(L20:L23) -> 0 | M24: =SUM(M20:M23) -> 0 | N24: =SUM(N20:N23) -> 0 | ... Q24: =SUM(Q20:Q23) -> 0
B25: Parámetros Notificaciones - CC1 | C25: =C24+1 -> 22 | F25: =VLOOKUP(E25,Parámetros!$B$13:$C$23,2,FALSE) -> Ninguna | G25: =J25+M25+P25+Q25 -> 0 | H25: =IF(E25=0,0,VLOOKUP(E25,Tabla!$C$6:$F$15,4,FALSE)) -> 0 | J25: =H25+I25 -> 0 | K25: =IF(E25=0,0,VLOOKUP(E25,Tabla!$C$6:$G$15,5,FALSE)) -> 0 | M25: =K25+L25 -> 0 | N25: =IF(E25=0,0,VLOOKUP(E25,Tabla!$C$6:$H$15,6,FALSE)) -> 0 | P25: =N25+O25 -> 0 | Q25: =IF(E25=0,0,VLOOKUP(E25,Tabla!$C$6:$I$15,7,FALSE)) -> 0 | S25: 393 | T25: 393 | W25: =+S25-G33 -> 393
C26: =C25+1 -> 23 | F26: =VLOOKUP(E26,Parámetros!$B$13:$C$23,2,FALSE) -> Ninguna | G26: =J26+M26+P26+Q26 -> 0 | H26: =IF(E26=0,0,VLOOKUP(E26,Tabla!$C$6:$F$15,4,FALSE)) -> 0 | J26: =H26+I26 -> 0 | K26: =IF(E26=0,0,VLOOKUP(E26,Tabla!$C$6:$G$15,5,FALSE)) -> 0 | M26: =K26+L26 -> 0 | N26: =IF(E26=0,0,VLOOKUP(E26,Tabla!$C$6:$H$15,6,FALSE)) -> 0 | P26: =N26+O26 -> 0 | Q26: =IF(E26=0,0,VLOOKUP(E26,Tabla!$C$6:$I$15,7,FALSE)) -> 0
C27: =C26+1 -> 24 | F27: =VLOOKUP(E27,Parámetros!$B$13:$C$23,2,FALSE) -> Ninguna | G27: =J27+M27+P27+Q27 -> 0 | H27: =IF(E27=0,0,VLOOKUP(E27,Tabla!$C$6:$F$15,4,FALSE)) -> 0 | J27: =H27+I27 -> 0 | K27: =IF(E27=0,0,VLOOKUP(E27,Tabla!$C$6:$G$15,5,FALSE)) -> 0 | M27: =K27+L27 -> 0 | N27: =IF(E27=0,0,VLOOKUP(E27,Tabla!$C$6:$H$15,6,FALSE)) -> 0 | P27: =N27+O27 -> 0 | Q27: =IF(E27=0,0,VLOOKUP(E27,Tabla!$C$6:$I$15,7,FALSE)) -> 0
C28: =C27+1 -> 25 | F28: =VLOOKUP(E28,Parámetros!$B$13:$C$23,2,FALSE) -> Ninguna | G28: =J28+M28+P28+Q28 -> 0 | H28: =IF(E28=0,0,VLOOKUP(E28,Tabla!$C$6:$F$15,4,FALSE)) -> 0 | J28: =H28+I28 -> 0 | K28: =IF(E28=0,0,VLOOKUP(E28,Tabla!$C$6:$G$15,5,FALSE)) -> 0 | M28: =K28+L28 -> 0 | N28: =IF(E28=0,0,VLOOKUP(E28,Tabla!$C$6:$H$15,6,FALSE)) -> 0 | P28: =N28+O28 -> 0 | Q28: =IF(E28=0,0,VLOOKUP(E28,Tabla!$C$6:$I$15,7,FALSE)) -> 0
C29: =C28+1 -> 26 | F29: =VLOOKUP(E29,Parámetros!$B$13:$C$23,2,FALSE) -> Ninguna | G29: =J29+M29+P29+Q29 -> 0 | H29: =IF(E29=0,0,VLOOKUP(E29,Tabla!$C$6:$F$15,4,FALSE)) -> 0 | J29: =H29+I29 -> 0 | K29: =IF(E29=0,0,VLOOKUP(E29,Tabla!$C$6:$G$15,5,FALSE)) -> 0 | M29: =K29+L29 -> 0 | N29: =IF(E29=0,0,VLOOKUP(E29,Tabla!$C$6:$H$15,6,FALSE)) -> 0 | P29: =N29+O29 -> 0 | Q29: =IF(E29=0,0,VLOOKUP(E29,Tabla!$C$6:$I$15,7,FALSE)) -> 0
C30: =C29+1 -> 27 | F30: =VLOOKUP(E30,Parámetros!$B$13:$C$23,2,FALSE) -> Ninguna | G30: =J30+M30+P30+Q30 -> 0 | H30: =IF(E30=0,0,VLOOKUP(E30,Tabla!$C$6:$F$15,4,FALSE)) -> 0 | J30: =H30+I30 -> 0 | K30: =IF(E30=0,0,VLOOKUP(E30,Tabla!$C$6:$G$15,5,FALSE)) -> 0 | M30: =K30+L30 -> 0 | N30: =IF(E30=0,0,VLOOKUP(E30,Tabla!$C$6:$H$15,6,FALSE)) -> 0 | P30: =N30+O30 -> 0 | Q30: =IF(E30=0,0,VLOOKUP(E30,Tabla!$C$6:$I$15,7,FALSE)) -> 0
C31: =C30+1 -> 28 | F31: =VLOOKUP(E31,Parámetros!$B$13:$C$23,2,FALSE) -> Ninguna | G31: =J31+M31+P31+Q31 -> 0 | H31: =IF(E31=0,0,VLOOKUP(E31,Tabla!$C$6:$F$15,4,FALSE)) -> 0 | J31: =H31+I31 -> 0 | K31: =IF(E31=0,0,VLOOKUP(E31,Tabla!$C$6:$G$15,5,FALSE)) -> 0 | M31: =K31+L31 -> 0 | N31: =IF(E31=0,0,VLOOKUP(E31,Tabla!$C$6:$H$15,6,FALSE)) -> 0 | P31: =N31+O31 -> 0 | Q31: =IF(E31=0,0,VLOOKUP(E31,Tabla!$C$6:$I$15,7,FALSE)) -> 0
C32: =C31+1 -> 29 | F32: =VLOOKUP(E32,Parámetros!$B$13:$C$23,2,FALSE) -> Ninguna | G32: =J32+M32+P32+Q32 -> 0 | H32: =IF(E32=0,0,VLOOKUP(E32,Tabla!$C$6:$F$15,4,FALSE)) -> 0 | J32: =H32+I32 -> 0 | K32: =IF(E32=0,0,VLOOKUP(E32,Tabla!$C$6:$G$15,5,FALSE)) -> 0 | M32: =K32+L32 -> 0 | N32: =IF(E32=0,0,VLOOKUP(E32,Tabla!$C$6:$H$15,6,FALSE)) -> 0 | P32: =N32+O32 -> 0 | Q32: =IF(E32=0,0,VLOOKUP(E32,Tabla!$C$6:$I$15,7,FALSE)) -> 0
C33: =C32+1 -> 30 | F33: =VLOOKUP(E33,Parámetros!$B$13:$C$17,2,FALSE) -> Ninguna | G33: =SUM(G25:G32) -> 0 | H33: =SUM(H25:H32) -> 0 | I33: =SUM(I25:I32) -> 0 | J33: =SUM(J25:J32) -> 0 | K33: =SUM(K25:K32) -> 0 | L33: =SUM(L25:L32) -> 0 | M33: =SUM(M25:M32) -> 0 | N33: =SUM(N25:N32) -> 0 | ... Q33: =SUM(Q25:Q32) -> 0
B34: Comisiones P2M - CC1 | C34: =C33+1 -> 31 | F34: =VLOOKUP(E34,Parámetros!$B$13:$C$23,2,FALSE) -> Ninguna | G34: =J34+M34+P34+Q34 -> 0 | H34: =IF(E34=0,0,VLOOKUP(E34,Tabla!$C$6:$F$15,4,FALSE)) -> 0 | J34: =H34+I34 -> 0 | K34: =IF(E34=0,0,VLOOKUP(E34,Tabla!$C$6:$G$15,5,FALSE)) -> 0 | M34: =K34+L34 -> 0 | N34: =IF(E34=0,0,VLOOKUP(E34,Tabla!$C$6:$H$15,6,FALSE)) -> 0 | P34: =N34+O34 -> 0 | Q34: =IF(E34=0,0,VLOOKUP(E34,Tabla!$C$6:$I$15,7,FALSE)) -> 0 | S34: 390 | T34: 390 | W34: =+S34-G43 -> 390
C35: =C34+1 -> 32 | F35: =VLOOKUP(E35,Parámetros!$B$13:$C$23,2,FALSE) -> Ninguna | G35: =J35+M35+P35+Q35 -> 0 | H35: =IF(E35=0,0,VLOOKUP(E35,Tabla!$C$6:$F$15,4,FALSE)) -> 0 | J35: =H35+I35 -> 0 | K35: =IF(E35=0,0,VLOOKUP(E35,Tabla!$C$6:$G$15,5,FALSE)) -> 0 | M35: =K35+L35 -> 0 | N35: =IF(E35=0,0,VLOOKUP(E35,Tabla!$C$6:$H$15,6,FALSE)) -> 0 | P35: =N35+O35 -> 0 | Q35: =IF(E35=0,0,VLOOKUP(E35,Tabla!$C$6:$I$15,7,FALSE)) -> 0
C36: =C35+1 -> 33 | F36: =VLOOKUP(E36,Parámetros!$B$13:$C$23,2,FALSE) -> Ninguna | G36: =J36+M36+P36+Q36 -> 0 | H36: =IF(E36=0,0,VLOOKUP(E36,Tabla!$C$6:$F$15,4,FALSE)) -> 0 | J36: =H36+I36 -> 0 | K36: =IF(E36=0,0,VLOOKUP(E36,Tabla!$C$6:$G$15,5,FALSE)) -> 0 | M36: =K36+L36 -> 0 | N36: =IF(E36=0,0,VLOOKUP(E36,Tabla!$C$6:$H$15,6,FALSE)) -> 0 | P36: =N36+O36 -> 0 | Q36: =IF(E36=0,0,VLOOKUP(E36,Tabla!$C$6:$I$15,7,FALSE)) -> 0
C37: =C36+1 -> 34 | F37: =VLOOKUP(E37,Parámetros!$B$13:$C$23,2,FALSE) -> Ninguna | G37: =J37+M37+P37+Q37 -> 0 | H37: =IF(E37=0,0,VLOOKUP(E37,Tabla!$C$6:$F$15,4,FALSE)) -> 0 | J37: =H37+I37 -> 0 | K37: =IF(E37=0,0,VLOOKUP(E37,Tabla!$C$6:$G$15,5,FALSE)) -> 0 | M37: =K37+L37 -> 0 | N37: =IF(E37=0,0,VLOOKUP(E37,Tabla!$C$6:$H$15,6,FALSE)) -> 0 | P37: =N37+O37 -> 0 | Q37: =IF(E37=0,0,VLOOKUP(E37,Tabla!$C$6:$I$15,7,FALSE)) -> 0
C38: =C37+1 -> 35 | F38: =VLOOKUP(E38,Parámetros!$B$13:$C$23,2,FALSE) -> Ninguna | G38: =J38+M38+P38+Q38 -> 0 | H38: =IF(E38=0,0,VLOOKUP(E38,Tabla!$C$6:$F$15,4,FALSE)) -> 0 | J38: =H38+I38 -> 0 | K38: =IF(E38=0,0,VLOOKUP(E38,Tabla!$C$6:$G$15,5,FALSE)) -> 0 | M38: =K38+L38 -> 0 | N38: =IF(E38=0,0,VLOOKUP(E38,Tabla!$C$6:$H$15,6,FALSE)) -> 0 | P38: =N38+O38 -> 0 | Q38: =IF(E38=0,0,VLOOKUP(E38,Tabla!$C$6:$I$15,7,FALSE)) -> 0
C39: =C38+1 -> 36 | F39: =VLOOKUP(E39,Parámetros!$B$13:$C$23,2,FALSE) -> Ninguna | G39: =J39+M39+P39+Q39 -> 0 | H39: =IF(E39=0,0,VLOOKUP(E39,Tabla!$C$6:$F$15,4,FALSE)) -> 0 | J39: =H39+I39 -> 0 | K39: =IF(E39=0,0,VLOOKUP(E39,Tabla!$C$6:$G$15,5,FALSE)) -> 0 | M39: =K39+L39 -> 0 | N39: =IF(E39=0,0,VLOOKUP(E39,Tabla!$C$6:$H$15,6,FALSE)) -> 0 | P39: =N39+O39 -> 0 | Q39: =IF(E39=0,0,VLOOKUP(E39,Tabla!$C$6:$I$15,7,FALSE)) -> 0
C40: =C39+1 -> 37 | F40: =VLOOKUP(E40,Parámetros!$B$13:$C$23,2,FALSE) -> Ninguna | G40: =J40+M40+P40+Q40 -> 0 | H40: =IF(E40=0,0,VLOOKUP(E40,Tabla!$C$6:$F$15,4,FALSE)) -> 0 | J40: =H40+I40 -> 0 | K40: =IF(E40=0,0,VLOOKUP(E40,Tabla!$C$6:$G$15,5,FALSE)) -> 0 | M40: =K40+L40 -> 0 | N40: =IF(E40=0,0,VLOOKUP(E40,Tabla!$C$6:$H$15,6,FALSE)) -> 0 | P40: =N40+O40 -> 0 | Q40: =IF(E40=0,0,VLOOKUP(E40,Tabla!$C$6:$I$15,7,FALSE)) -> 0
...

Sheet Tabla
A1: Tabla de niveles de dificultad
J2: 0.2 | Q2: 0.5 | U2: 0.25 | Y2: 0.05
A3: Requerimiento | C3: Dificultad | E3: TOTAL | F3: Total Diseño | G3: Total Desarrollo | H3: Total Testing | I3: Total Otros | J3: Análisis & Diseño | P3: Desarrollo | U3: Testing | Y3: Otros
C4: Código | D4: Descripción | J4: Análisis | K4: UX/UI | L4: Diseño | M4: Arquitectura | N4: Elaboración de Casos de Pruebas | O4: Total Diseño | P4: Desarrollo | Q4: Desarrollo Tecnología | R4: Pruebas Unitarias | S4: Documentación | T4: Total Desarrollo | U4: Preparación de Datos | V4: Pruebas Integrales | W4: Pruebas No Funcionales | X4: Total Testing | Y4: Elaboración de Pase | Z4: Soporte Incidencias | AA4: Total Otros
J5: 0.06 | K5: 0 | L5: 0.04 | M5: 0 | N5: 0 | Q5: 0.38 | R5: 0.08 | S5: 0.04 | U5: 0.03 | V5: 0.2 | W5: 0.02 | Y5: 0.03 | Z5: 0.04
A6: Se considera: Tratar registros de una tabla Generación de un archivo (hasta un objeto) Cálculo sencillo (hasta dos objetos) | C6: 1 | D6: Muy Baja | E6: =+O6+T6+X6+AA6 -> 10.64 | F6: =+O6 -> 1.24 | G6: =+T6 -> 6.2 | H6: =+X6 -> 2.5 | I6: =+AA6 -> 0.7 | J6: =+$J$5*$T6/$Q$2 -> 0.744 | K6: =+$K$5*$T6/$Q$2 -> 0 | L6: =+$L$5*$T6/$Q$2 -> 0.496 | M6: =+$M$5*$T6/$Q$2 -> 0 | N6: =+$N$5*$T6/$Q$2 -> 0 | O6: =SUM(J6:N6) -> 1.24 | P6: 5 | Q6: =+P6*$S$17 -> 5 | R6: =+Q6*$R$5/$Q$2 -> 0.8 | S6: =+Q6*$S$5/$Q$2 -> 0.4 | T6: =SUM(Q6:S6) -> 6.2 | U6: =+$U$5*$Q6/$Q$2 -> 0.3 | V6: =+$V$5*$Q6/$Q$2 -> 2 | W6: =+$W$5*$Q6/$Q$2 -> 0.2 | X6: =SUM(U6:W6) -> 2.5 | Y6: =+$Y$5*$Q6/$Q$2 -> 0.3 | Z6: =+$Z$5*$Q6/$Q$2 -> 0.4 | AA6: =SUM(Y6:Z6) -> 0.7
A7: Se considera: Relacionar registros entre dos tablas Generación de archivos (hasta dos objetos) Cálculo sencillo (hasta dos objetos) Mantenimiento de tipo Cabecera únicamente, hasta 5 objetos Reportes sencillos (listados tabulares con formato simple) | C7: 2 | D7: Baja | E7: =+O7+T7+X7+AA7 -> 14.896 | F7: =+O7 -> 1.736 | G7: =+T7 -> 8.68 | H7: =+X7 -> 3.5 | I7: =+AA7 -> 0.98 | J7: =+$J$5*$T7/$Q$2 -> 1.0416 | K7: =+$K$5*$T7/$Q$2 -> 0 | L7: =+$L$5*$T7/$Q$2 -> 0.6944 | M7: =+$M$5*$T7/$Q$2 -> 0 | N7: =+$N$5*$T7/$Q$2 -> 0 | O7: =SUM(J7:N7) -> 1.736 | P7: 7 | Q7: =+P7*$S$17 -> 7 | R7: =+Q7*$R$5/$Q$2 -> 1.12 | S7: =+Q7*$S$5/$Q$2 -> 0.56 | T7: =SUM(Q7:S7) -> 8.68 | U7: =+$U$5*$Q7/$Q$2 -> 0.42 | V7: =+$V$5*$Q7/$Q$2 -> 2.8 | W7: =+$W$5*$Q7/$Q$2 -> 0.28 | X7: =SUM(U7:W7) -> 3.5 | Y7: =+$Y$5*$Q7/$Q$2 -> 0.42 | Z7: =+$Z$5*$Q7/$Q$2 -> 0.56 | AA7: =SUM(Y7:Z7) -> 0.98
A8: Se considera: Relacionar registros hasta cuatro tablas Generación de archivos (hasta cuatro objetos) Cálculo sencillo (hasta cuatro objetos) Mantenimiento de tipo Cabecera únicamente, hasta 10 objetos Reportes sencillos (listados tabulares con formato standar) | C8: 3 | D8: Media Baja | E8: =+O8+T8+X8+AA8 -> 21.28 | F8: =+O8 -> 2.48 | G8: =+T8 -> 12.4 | H8: =+X8 -> 5 | I8: =+AA8 -> 1.4 | J8: =+$J$5*$T8/$Q$2 -> 1.488 | K8: =+$K$5*$T8/$Q$2 -> 0 | L8: =+$L$5*$T8/$Q$2 -> 0.992 | M8: =+$M$5*$T8/$Q$2 -> 0 | N8: =+$N$5*$T8/$Q$2 -> 0 | O8: =SUM(J8:N8) -> 2.48 | P8: 10 | Q8: =+P8*$S$17 -> 10 | R8: =+Q8*$R$5/$Q$2 -> 1.6 | S8: =+Q8*$S$5/$Q$2 -> 0.8 | T8: =SUM(Q8:S8) -> 12.4 | U8: =+$U$5*$Q8/$Q$2 -> 0.6 | V8: =+$V$5*$Q8/$Q$2 -> 4 | W8: =+$W$5*$Q8/$Q$2 -> 0.4 | X8: =SUM(U8:W8) -> 5 | Y8: =+$Y$5*$Q8/$Q$2 -> 0.6 | Z8: =+$Z$5*$Q8/$Q$2 -> 0.8 | AA8: =SUM(Y8:Z8) -> 1.4
A9: Se considera: Administración de objetos (incluye la impresión) Mantenimiento de tipo Cabecera/Detalle Generación de archivos (hasta seis objetos) Obtener información de otros sistemas Cálculo mediano (entre 5 y 6 objetos, mismo módulo) Reportes con formato simple y hasta un quiebre | C9: 4 | D9: Media | E9: =+O9+T9+X9+AA9 -> 29.792 | F9: =+O9 -> 3.472 | G9: =+T9 -> 17.36 | H9: =+X9 -> 7 | I9: =+AA9 -> 1.96 | J9: =+$J$5*$T9/$Q$2 -> 2.0832 | K9: =+$K$5*$T9/$Q$2 -> 0 | L9: =+$L$5*$T9/$Q$2 -> 1.3888 | M9: =+$M$5*$T9/$Q$2 -> 0 | N9: =+$N$5*$T9/$Q$2 -> 0 | O9: =SUM(J9:N9) -> 3.472 | P9: 14 | Q9: =+P9*$S$17 -> 14 | R9: =+Q9*$R$5/$Q$2 -> 2.24 | S9: =+Q9*$S$5/$Q$2 -> 1.12 | T9: =SUM(Q9:S9) -> 17.36 | U9: =+$U$5*$Q9/$Q$2 -> 0.84 | V9: =+$V$5*$Q9/$Q$2 -> 5.6 | W9: =+$W$5*$Q9/$Q$2 -> 0.56 | X9: =SUM(U9:W9) -> 7 | Y9: =+$Y$5*$Q9/$Q$2 -> 0.84 | Z9: =+$Z$5*$Q9/$Q$2 -> 1.12 | AA9: =SUM(Y9:Z9) -> 1.96
A10: Se considera: Administración de objetos (incluye la impresión) Mantenimiento de tipo Cabecera/Detalle Generación de archivos (hasta seis objetos) Obtener información de otros sistemas Cálculo mediano (entre 6 y 7 objetos, mismo módulo) Reportes con formato simple y hasta dos quiebres | C10: 5 | D10: Media Alta | E10: =+O10+T10+X10+AA10 -> 38.304 | F10: =+O10 -> 4.464 | G10: =+T10 -> 22.32 | H10: =+X10 -> 9 | I10: =+AA10 -> 2.52 | J10: =+$J$5*$T10/$Q$2 -> 2.6784 | K10: =+$K$5*$T10/$Q$2 -> 0 | L10: =+$L$5*$T10/$Q$2 -> 1.7856 | M10: =+$M$5*$T10/$Q$2 -> 0 | N10: =+$N$5*$T10/$Q$2 -> 0 | O10: =SUM(J10:N10) -> 4.464 | P10: 18 | Q10: =+P10*$S$17 -> 18 | R10: =+Q10*$R$5/$Q$2 -> 2.88 | S10: =+Q10*$S$5/$Q$2 -> 1.44 | T10: =SUM(Q10:S10) -> 22.32 | U10: =+$U$5*$Q10/$Q$2 -> 1.08 | V10: =+$V$5*$Q10/$Q$2 -> 7.2 | W10: =+$W$5*$Q10/$Q$2 -> 0.72 | X10: =SUM(U10:W10) -> 9 | Y10: =+$Y$5*$Q10/$Q$2 -> 1.08 | Z10: =+$Z$5*$Q10/$Q$2 -> 1.44 | AA10: =SUM(Y10:Z10) -> 2.52
A11: Se considera: Mantenimiento de tipo Cabecera/Detalle/Detalle Cálculo mediano (entre 7 y 8 objetos, diferentes módulos) Reportes con formato elaborado y hasta tres quiebres | C11: 6 | D11: Alta | E11: =+O11+T11+X11+AA11 -> 46.816 | F11: =+O11 -> 5.456 | G11: =+T11 -> 27.28 | H11: =+X11 -> 11 | I11: =+AA11 -> 3.08 | J11: =+$J$5*$T11/$Q$2 -> 3.2736 | K11: =+$K$5*$T11/$Q$2 -> 0 | L11: =+$L$5*$T11/$Q$2 -> 2.1824 | M11: =+$M$5*$T11/$Q$2 -> 0 | N11: =+$N$5*$T11/$Q$2 -> 0 | O11: =SUM(J11:N11) -> 5.456 | P11: 22 | Q11: =+P11*$S$17 -> 22 | R11: =+Q11*$R$5/$Q$2 -> 3.52 | S11: =+Q11*$S$5/$Q$2 -> 1.76 | T11: =SUM(Q11:S11) -> 27.28 | U11: =+$U$5*$Q11/$Q$2 -> 1.32 | V11: =+$V$5*$Q11/$Q$2 -> 8.8 | W11: =+$W$5*$Q11/$Q$2 -> 0.88 | X11: =SUM(U11:W11) -> 11 | Y11: =+$Y$5*$Q11/$Q$2 -> 1.32 | Z11: =+$Z$5*$Q11/$Q$2 -> 1.76 | AA11: =SUM(Y11:Z11) -> 3.08
A12: Se considera: Mantenimiento principal que depende de otros Cálculo mixto (hasta 10 objetos) Reportes con cálculos elaborados, formato personalizado Interfaces con otro sistema (1) | C12: 7 | D12: Muy Alta | E12: =+O12+T12+X12+AA12 -> 63.84 | F12: =+O12 -> 7.44 | G12: =+T12 -> 37.2 | H12: =+X12 -> 15 | I12: =+AA12 -> 4.2 | J12: =+$J$5*$T12/$Q$2 -> 4.464 | K12: =+$K$5*$T12/$Q$2 -> 0 | L12: =+$L$5*$T12/$Q$2 -> 2.976 | M12: =+$M$5*$T12/$Q$2 -> 0 | N12: =+$N$5*$T12/$Q$2 -> 0 | O12: =SUM(J12:N12) -> 7.44 | P12: 30 | Q12: =+P12*$S$17 -> 30 | R12: =+Q12*$R$5/$Q$2 -> 4.8 | S12: =+Q12*$S$5/$Q$2 -> 2.4 | T12: =SUM(Q12:S12) -> 37.2 | U12: =+$U$5*$Q12/$Q$2 -> 1.8 | V12: =+$V$5*$Q12/$Q$2 -> 12 | W12: =+$W$5*$Q12/$Q$2 -> 1.2 | X12: =SUM(U12:W12) -> 15 | Y12: =+$Y$5*$Q12/$Q$2 -> 1.8 | Z12: =+$Z$5*$Q12/$Q$2 -> 2.4 | AA12: =SUM(Y12:Z12) -> 4.2
A13: Se considera: Cálculo complejo (hasta 15 objetos) Reportes con cálculos complejos, formato personalizado Interfaces con otro sistema Proceso que se deriva de cálculos precedentes en el sistema | C13: 8 | D13: Compleja | E13: =+O13+T13+X13+AA13 -> 85.12 | F13: =+O13 -> 9.92 | G13: =+T13 -> 49.6 | H13: =+X13 -> 20 | I13: =+AA13 -> 5.6 | J13: =+$J$5*$T13/$Q$2 -> 5.952 | K13: =+$K$5*$T13/$Q$2 -> 0 | L13: =+$L$5*$T13/$Q$2 -> 3.968 | M13: =+$M$5*$T13/$Q$2 -> 0 | N13: =+$N$5*$T13/$Q$2 -> 0 | O13: =SUM(J13:N13) -> 9.92 | P13: 40 | Q13: =+P13*$S$17 -> 40 | R13: =+Q13*$R$5/$Q$2 -> 6.4 | S13: =+Q13*$S$5/$Q$2 -> 3.2 | T13: =SUM(Q13:S13) -> 49.6 | U13: =+$U$5*$Q13/$Q$2 -> 2.4 | V13: =+$V$5*$Q13/$Q$2 -> 16 | W13: =+$W$5*$Q13/$Q$2 -> 1.6 | X13: =SUM(U13:W13) -> 20 | Y13: =+$Y$5*$Q13/$Q$2 -> 2.4 | Z13: =+$Z$5*$Q13/$Q$2 -> 3.2 | AA13: =SUM(Y13:Z13) -> 5.6
A14: Se considera: Cálculo complejo (hasta 20 objetos) Reportes con cálculos complejos, formato elaborado y personalizado Interfaces con otros sistemas externos Proceso que se deriva de cálculos precedentes en el sistema Proceso que trabaja grandes volumenes de datos Proceso que implica como condición la ejecución de operaciones de otras opciones del sistema para llegar al requerimiento solicitado. | C14: 9 | D14: Muy Compleja | E14: =+O14+T14+X14+AA14 -> 106.4 | F14: =+O14 -> 12.4 | G14: =+T14 -> 62 | H14: =+X14 -> 25 | I14: =+AA14 -> 7 | J14: =+$J$5*$T14/$Q$2 -> 7.44 | K14: =+$K$5*$T14/$Q$2 -> 0 | L14: =+$L$5*$T14/$Q$2 -> 4.96 | M14: =+$M$5*$T14/$Q$2 -> 0 | N14: =+$N$5*$T14/$Q$2 -> 0 | O14: =SUM(J14:N14) -> 12.4 | P14: 50 | Q14: =+P14*$S$17 -> 50 | R14: =+Q14*$R$5/$Q$2 -> 8 | S14: =+Q14*$S$5/$Q$2 -> 4 | T14: =SUM(Q14:S14) -> 62 | U14: =+$U$5*$Q14/$Q$2 -> 3 | V14: =+$V$5*$Q14/$Q$2 -> 20 | W14: =+$W$5*$Q14/$Q$2 -> 2 | X14: =SUM(U14:W14) -> 25 | Y14: =+$Y$5*$Q14/$Q$2 -> 3 | Z14: =+$Z$5*$Q14/$Q$2 -> 4 | AA14: =SUM(Y14:Z14) -> 7
A15: Se considera: Cálculo complejo (hasta 25 objetos) Reportes con cálculos complejos, formato elaborado y personalizado Interfaces con otros sistemas externos Proceso que trabaja grandes volumenes de datos Proceso que implica como condición la ejecución de operaciones de otras opciones del sistema para llegar al requerimiento solicitado. Uso de nueva tecnología Actualizaciones complejas a BD Testing complejo | C15: 10 | D15: Extrema | E15: =+O15+T15+X15+AA15 -> 127.68 | F15: =+O15 -> 14.88 | G15: =+T15 -> 74.4 | H15: =+X15 -> 30 | I15: =+AA15 -> 8.4 | J15: =+$J$5*$T15/$Q$2 -> 8.928 | K15: =+$K$5*$T15/$Q$2 -> 0 | L15: =+$L$5*$T15/$Q$2 -> 5.952 | M15: =+$M$5*$T15/$Q$2 -> 0 | N15: =+$N$5*$T15/$Q$2 -> 0 | O15: =SUM(J15:N15) -> 14.88 | P15: 60 | Q15: =+P15*$S$17 -> 60 | R15: =+Q15*$R$5/$Q$2 -> 9.6 | S15: =+Q15*$S$5/$Q$2 -> 4.8 | T15: =SUM(Q15:S15) -> 74.4 | U15: =+$U$5*$Q15/$Q$2 -> 3.6 | V15: =+$V$5*$Q15/$Q$2 -> 24 | W15: =+$W$5*$Q15/$Q$2 -> 2.4 | X15: =SUM(U15:W15) -> 30 | Y15: =+$Y$5*$Q15/$Q$2 -> 3.6 | Z15: =+$Z$5*$Q15/$Q$2 -> 4.8 | AA15: =SUM(Y15:Z15) -> 8.4
P17: Tecnología | R17: Power Builder | S17: =VLOOKUP(R17,Parámetros!$B$4:$C$10,2,FALSE) -> 1
Q110: 8
Q111: 40 | U111: =6000+300+630 -> 6930
Q112: 16
Q113: 16
Q114: 32
Q115: 15
Q116: 20
Q117: 20
Q118: 7.5
Q119: 40
Q120: 20
Q121: 25
Q122: 15
Q123: 20
... Q242: 4
Q243: 1 hr
Q244: 80
Q245: 80
Q246: 0
Q247: 40
Q248: 40
Q249: 6
Q250: 14
Q251: 8
...

Sheet Parámetros
B2: Tecnología de Desarrollo
B3: Lenguaje | C3: Peso
B4: .NET | C4: 1.5
B5: Java | C5: 1.7
B6: PHP | C6: 1.7
B7: Python | C7: 1.5
B8: IOS | C8: 2
B9: Android | C9: 1.5
B10: Power Builder | C10: 1
B12: Dificultad
B13: 0 | C13: Ninguna
B14: 1 | C14: Muy Baja
B15: 2 | C15: Baja
B16: 3 | C16: Media Baja
B17: 4 | C17: Media
B18: 5 | C18: Media Alta
B19: 6 | C19: Alta
B20: 7 | C20: Muy Alta
B21: 8 | C21: Compleja
B22: 9 | C22: Muy Compleja
B23: 10 | C23: Extremo

Sheet Hoja1
C2: ¿Porque? | D2: Situación Actual | E2: El mundo ideal | F2: Pre Venta | G2: On Going
C3: Ser asertivos en la estimación, disminuir desviaciones de lo que realmente se necesita para atender una necesidad | D3: Basado en juicio experto. Por lo tanto depende de la experiencia y conocimiento de quien lo haga | E3: Cuando mas detalle se tenga del alcance se puede mejorar la precisión | F3: RSIS o US | G3: Componentes/Objetos (resultado del A&D) o US Refinados

Sheet Estimacion
B5: SECCIÓN DESARROLLO Y PRUEBAS UNITARIAS
B6: Nro. | C6: ACTIVIDAD | D6: HORAS
B7: 1 | C7: Evaluacion y Aseguramiento | D7: =0.15*Requerimientos!G55 -> 13.7064
B8: 2 | C8: Análisis Funcional y Técnico | D8: =Requerimientos!J55 -> 10.416
B9: 4 | C9: Desarrollo | D9: =Requerimientos!M55 -> 54.08
B10: 6 | C10: Testing | D10: =Requerimientos!P55 -> 21
B11: 7 | C11: Otros | D11: =Requerimientos!Q55 -> 5.88
B12: Total | D12: =SUM(D7:D11) -> 105.0824
